<?xml version="1.0" encoding="UTF-8"?>
<testng-results skipped="0" failed="2" ignored="0" total="3" passed="1">
  <reporter-output>
  </reporter-output>
  <suite name="nEXCITIZEN" duration-ms="148557" started-at="2019-12-19T06:49:57Z" finished-at="2019-12-19T06:52:26Z">
    <groups>
    </groups>
    <test name="nEXCITIZEN_TestCase1" duration-ms="148557" started-at="2019-12-19T06:49:57Z" finished-at="2019-12-19T06:52:26Z">
      <class name="com.TestCase.RegistrationandLoginTestCase_Folder.Login_TestCase">
        <test-method status="PASS" signature="Url_login()[pri:0, instance:com.TestCase.RegistrationandLoginTestCase_Folder.Login_TestCase@6e06451e]" name="Url_login" is-config="true" duration-ms="20194" started-at="2019-12-19T06:49:57Z" finished-at="2019-12-19T06:50:17Z">
          <reporter-output>
          </reporter-output>
        </test-method> <!-- Url_login -->
        <test-method status="FAIL" signature="Without_Username()[pri:1, instance:com.TestCase.RegistrationandLoginTestCase_Folder.Login_TestCase@6e06451e]" name="Without_Username" duration-ms="62077" started-at="2019-12-19T06:50:17Z" finished-at="2019-12-19T06:51:19Z">
          <exception class="java.lang.AssertionError">
            <message>
              <![CDATA[WithOut UserName Not Successfully login expected [true] but found [false]]]>
            </message>
            <full-stacktrace>
              <![CDATA[java.lang.AssertionError: WithOut UserName Not Successfully login expected [true] but found [false]
at org.testng.Assert.fail(Assert.java:96)
at org.testng.Assert.failNotEquals(Assert.java:776)
at org.testng.Assert.assertTrue(Assert.java:44)
at com.PageObject.New_Registration.Login_Page.OnlyPassWordtest(Login_Page.java:48)
at com.TestCase.RegistrationandLoginTestCase_Folder.Login_TestCase.Without_Username(Login_TestCase.java:17)
at sun.reflect.NativeMethodAccessorImpl.invoke0(Native Method)
at sun.reflect.NativeMethodAccessorImpl.invoke(NativeMethodAccessorImpl.java:62)
at sun.reflect.DelegatingMethodAccessorImpl.invoke(DelegatingMethodAccessorImpl.java:43)
at java.lang.reflect.Method.invoke(Method.java:498)
at org.testng.internal.MethodInvocationHelper.invokeMethod(MethodInvocationHelper.java:124)
at org.testng.internal.Invoker.invokeMethod(Invoker.java:583)
at org.testng.internal.Invoker.invokeTestMethod(Invoker.java:719)
at org.testng.internal.Invoker.invokeTestMethods(Invoker.java:989)
at org.testng.internal.TestMethodWorker.invokeTestMethods(TestMethodWorker.java:125)
at org.testng.internal.TestMethodWorker.run(TestMethodWorker.java:109)
at org.testng.TestRunner.privateRun(TestRunner.java:648)
at org.testng.TestRunner.run(TestRunner.java:505)
at org.testng.SuiteRunner.runTest(SuiteRunner.java:455)
at org.testng.SuiteRunner.runSequentially(SuiteRunner.java:450)
at org.testng.SuiteRunner.privateRun(SuiteRunner.java:415)
at org.testng.SuiteRunner.run(SuiteRunner.java:364)
at org.testng.SuiteRunnerWorker.runSuite(SuiteRunnerWorker.java:52)
at org.testng.SuiteRunnerWorker.run(SuiteRunnerWorker.java:84)
at org.testng.TestNG.runSuitesSequentially(TestNG.java:1208)
at org.testng.TestNG.runSuitesLocally(TestNG.java:1137)
at org.testng.TestNG.runSuites(TestNG.java:1049)
at org.testng.TestNG.run(TestNG.java:1017)
at org.testng.IDEARemoteTestNG.run(IDEARemoteTestNG.java:73)
at org.testng.RemoteTestNGStarter.main(RemoteTestNGStarter.java:123)
]]>
            </full-stacktrace>
          </exception> <!-- java.lang.AssertionError -->
          <reporter-output>
          </reporter-output>
        </test-method> <!-- Without_Username -->
        <test-method status="FAIL" signature="Without_Password()[pri:2, instance:com.TestCase.RegistrationandLoginTestCase_Folder.Login_TestCase@6e06451e]" name="Without_Password" duration-ms="62037" started-at="2019-12-19T06:51:19Z" finished-at="2019-12-19T06:52:21Z">
          <exception class="java.lang.AssertionError">
            <message>
              <![CDATA[WithOut password Not Successfully login expected [true] but found [false]]]>
            </message>
            <full-stacktrace>
              <![CDATA[java.lang.AssertionError: WithOut password Not Successfully login expected [true] but found [false]
at org.testng.Assert.fail(Assert.java:96)
at org.testng.Assert.failNotEquals(Assert.java:776)
at org.testng.Assert.assertTrue(Assert.java:44)
at com.PageObject.New_Registration.Login_Page.OnlyUserNametest(Login_Page.java:74)
at com.TestCase.RegistrationandLoginTestCase_Folder.Login_TestCase.Without_Password(Login_TestCase.java:21)
at sun.reflect.NativeMethodAccessorImpl.invoke0(Native Method)
at sun.reflect.NativeMethodAccessorImpl.invoke(NativeMethodAccessorImpl.java:62)
at sun.reflect.DelegatingMethodAccessorImpl.invoke(DelegatingMethodAccessorImpl.java:43)
at java.lang.reflect.Method.invoke(Method.java:498)
at org.testng.internal.MethodInvocationHelper.invokeMethod(MethodInvocationHelper.java:124)
at org.testng.internal.Invoker.invokeMethod(Invoker.java:583)
at org.testng.internal.Invoker.invokeTestMethod(Invoker.java:719)
at org.testng.internal.Invoker.invokeTestMethods(Invoker.java:989)
at org.testng.internal.TestMethodWorker.invokeTestMethods(TestMethodWorker.java:125)
at org.testng.internal.TestMethodWorker.run(TestMethodWorker.java:109)
at org.testng.TestRunner.privateRun(TestRunner.java:648)
at org.testng.TestRunner.run(TestRunner.java:505)
at org.testng.SuiteRunner.runTest(SuiteRunner.java:455)
at org.testng.SuiteRunner.runSequentially(SuiteRunner.java:450)
at org.testng.SuiteRunner.privateRun(SuiteRunner.java:415)
at org.testng.SuiteRunner.run(SuiteRunner.java:364)
at org.testng.SuiteRunnerWorker.runSuite(SuiteRunnerWorker.java:52)
at org.testng.SuiteRunnerWorker.run(SuiteRunnerWorker.java:84)
at org.testng.TestNG.runSuitesSequentially(TestNG.java:1208)
at org.testng.TestNG.runSuitesLocally(TestNG.java:1137)
at org.testng.TestNG.runSuites(TestNG.java:1049)
at org.testng.TestNG.run(TestNG.java:1017)
at org.testng.IDEARemoteTestNG.run(IDEARemoteTestNG.java:73)
at org.testng.RemoteTestNGStarter.main(RemoteTestNGStarter.java:123)
]]>
            </full-stacktrace>
          </exception> <!-- java.lang.AssertionError -->
          <reporter-output>
          </reporter-output>
        </test-method> <!-- Without_Password -->
        <test-method status="PASS" signature="Orginal_user_pass()[pri:3, instance:com.TestCase.RegistrationandLoginTestCase_Folder.Login_TestCase@6e06451e]" name="Orginal_user_pass" duration-ms="4136" started-at="2019-12-19T06:52:21Z" finished-at="2019-12-19T06:52:26Z">
          <reporter-output>
          </reporter-output>
        </test-method> <!-- Orginal_user_pass -->
      </class> <!-- com.TestCase.RegistrationandLoginTestCase_Folder.Login_TestCase -->
    </test> <!-- nEXCITIZEN_TestCase1 -->
  </suite> <!-- nEXCITIZEN -->
</testng-results>
