<?xml version="1.0" encoding="UTF-8"?>
<testng-results skipped="0" failed="3" ignored="0" total="5" passed="2">
  <reporter-output>
  </reporter-output>
  <suite name="nEXCITIZEN" duration-ms="368980" started-at="2019-12-19T08:26:13Z" finished-at="2019-12-19T08:32:22Z">
    <groups>
    </groups>
    <test name="nEXCITIZEN_TestCase1" duration-ms="368980" started-at="2019-12-19T08:26:13Z" finished-at="2019-12-19T08:32:22Z">
      <class name="com.TestCase.RegistrationandLoginTestCase_Folder.Login_TestCase">
        <test-method status="PASS" signature="Url_login()[pri:0, instance:com.TestCase.RegistrationandLoginTestCase_Folder.Login_TestCase@59494225]" name="Url_login" is-config="true" duration-ms="25872" started-at="2019-12-19T08:26:13Z" finished-at="2019-12-19T08:26:39Z">
          <reporter-output>
          </reporter-output>
        </test-method> <!-- Url_login -->
        <test-method status="FAIL" signature="Without_Username()[pri:1, instance:com.TestCase.RegistrationandLoginTestCase_Folder.Login_TestCase@59494225]" name="Without_Username" duration-ms="62252" started-at="2019-12-19T08:26:39Z" finished-at="2019-12-19T08:27:41Z">
          <exception class="java.lang.AssertionError">
            <message>
              <![CDATA[WithOut UserName Not Successfully login expected [true] but found [false]]]>
            </message>
            <full-stacktrace>
              <![CDATA[java.lang.AssertionError: WithOut UserName Not Successfully login expected [true] but found [false]
at org.testng.Assert.fail(Assert.java:96)
at org.testng.Assert.failNotEquals(Assert.java:776)
at org.testng.Assert.assertTrue(Assert.java:44)
at com.PageObject.New_Registration.Login_Page.OnlyPassWordtest(Login_Page.java:48)
at com.TestCase.RegistrationandLoginTestCase_Folder.Login_TestCase.Without_Username(Login_TestCase.java:17)
at sun.reflect.NativeMethodAccessorImpl.invoke0(Native Method)
at sun.reflect.NativeMethodAccessorImpl.invoke(NativeMethodAccessorImpl.java:62)
at sun.reflect.DelegatingMethodAccessorImpl.invoke(DelegatingMethodAccessorImpl.java:43)
at java.lang.reflect.Method.invoke(Method.java:498)
at org.testng.internal.MethodInvocationHelper.invokeMethod(MethodInvocationHelper.java:124)
at org.testng.internal.Invoker.invokeMethod(Invoker.java:583)
at org.testng.internal.Invoker.invokeTestMethod(Invoker.java:719)
at org.testng.internal.Invoker.invokeTestMethods(Invoker.java:989)
at org.testng.internal.TestMethodWorker.invokeTestMethods(TestMethodWorker.java:125)
at org.testng.internal.TestMethodWorker.run(TestMethodWorker.java:109)
at org.testng.TestRunner.privateRun(TestRunner.java:648)
at org.testng.TestRunner.run(TestRunner.java:505)
at org.testng.SuiteRunner.runTest(SuiteRunner.java:455)
at org.testng.SuiteRunner.runSequentially(SuiteRunner.java:450)
at org.testng.SuiteRunner.privateRun(SuiteRunner.java:415)
at org.testng.SuiteRunner.run(SuiteRunner.java:364)
at org.testng.SuiteRunnerWorker.runSuite(SuiteRunnerWorker.java:52)
at org.testng.SuiteRunnerWorker.run(SuiteRunnerWorker.java:84)
at org.testng.TestNG.runSuitesSequentially(TestNG.java:1208)
at org.testng.TestNG.runSuitesLocally(TestNG.java:1137)
at org.testng.TestNG.runSuites(TestNG.java:1049)
at org.testng.TestNG.run(TestNG.java:1017)
at org.testng.IDEARemoteTestNG.run(IDEARemoteTestNG.java:73)
at org.testng.RemoteTestNGStarter.main(RemoteTestNGStarter.java:123)
]]>
            </full-stacktrace>
          </exception> <!-- java.lang.AssertionError -->
          <reporter-output>
          </reporter-output>
        </test-method> <!-- Without_Username -->
        <test-method status="FAIL" signature="Without_Password()[pri:2, instance:com.TestCase.RegistrationandLoginTestCase_Folder.Login_TestCase@59494225]" name="Without_Password" duration-ms="61718" started-at="2019-12-19T08:27:41Z" finished-at="2019-12-19T08:28:43Z">
          <exception class="java.lang.AssertionError">
            <message>
              <![CDATA[WithOut password Not Successfully login expected [true] but found [false]]]>
            </message>
            <full-stacktrace>
              <![CDATA[java.lang.AssertionError: WithOut password Not Successfully login expected [true] but found [false]
at org.testng.Assert.fail(Assert.java:96)
at org.testng.Assert.failNotEquals(Assert.java:776)
at org.testng.Assert.assertTrue(Assert.java:44)
at com.PageObject.New_Registration.Login_Page.OnlyUserNametest(Login_Page.java:74)
at com.TestCase.RegistrationandLoginTestCase_Folder.Login_TestCase.Without_Password(Login_TestCase.java:21)
at sun.reflect.NativeMethodAccessorImpl.invoke0(Native Method)
at sun.reflect.NativeMethodAccessorImpl.invoke(NativeMethodAccessorImpl.java:62)
at sun.reflect.DelegatingMethodAccessorImpl.invoke(DelegatingMethodAccessorImpl.java:43)
at java.lang.reflect.Method.invoke(Method.java:498)
at org.testng.internal.MethodInvocationHelper.invokeMethod(MethodInvocationHelper.java:124)
at org.testng.internal.Invoker.invokeMethod(Invoker.java:583)
at org.testng.internal.Invoker.invokeTestMethod(Invoker.java:719)
at org.testng.internal.Invoker.invokeTestMethods(Invoker.java:989)
at org.testng.internal.TestMethodWorker.invokeTestMethods(TestMethodWorker.java:125)
at org.testng.internal.TestMethodWorker.run(TestMethodWorker.java:109)
at org.testng.TestRunner.privateRun(TestRunner.java:648)
at org.testng.TestRunner.run(TestRunner.java:505)
at org.testng.SuiteRunner.runTest(SuiteRunner.java:455)
at org.testng.SuiteRunner.runSequentially(SuiteRunner.java:450)
at org.testng.SuiteRunner.privateRun(SuiteRunner.java:415)
at org.testng.SuiteRunner.run(SuiteRunner.java:364)
at org.testng.SuiteRunnerWorker.runSuite(SuiteRunnerWorker.java:52)
at org.testng.SuiteRunnerWorker.run(SuiteRunnerWorker.java:84)
at org.testng.TestNG.runSuitesSequentially(TestNG.java:1208)
at org.testng.TestNG.runSuitesLocally(TestNG.java:1137)
at org.testng.TestNG.runSuites(TestNG.java:1049)
at org.testng.TestNG.run(TestNG.java:1017)
at org.testng.IDEARemoteTestNG.run(IDEARemoteTestNG.java:73)
at org.testng.RemoteTestNGStarter.main(RemoteTestNGStarter.java:123)
]]>
            </full-stacktrace>
          </exception> <!-- java.lang.AssertionError -->
          <reporter-output>
          </reporter-output>
        </test-method> <!-- Without_Password -->
        <test-method status="PASS" signature="Orginal_user_pass()[pri:3, instance:com.TestCase.RegistrationandLoginTestCase_Folder.Login_TestCase@59494225]" name="Orginal_user_pass" duration-ms="3446" started-at="2019-12-19T08:28:43Z" finished-at="2019-12-19T08:28:47Z">
          <reporter-output>
          </reporter-output>
        </test-method> <!-- Orginal_user_pass -->
      </class> <!-- com.TestCase.RegistrationandLoginTestCase_Folder.Login_TestCase -->
      <class name="com.TestCase.RegistrationandLoginTestCase_Folder.Application_TestCase">
        <test-method status="FAIL" signature="Hit_Application()[pri:4, instance:com.TestCase.RegistrationandLoginTestCase_Folder.Application_TestCase@6e1567f1]" name="Hit_Application" duration-ms="182620" started-at="2019-12-19T08:28:47Z" finished-at="2019-12-19T08:31:49Z">
          <exception class="java.lang.AssertionError">
            <message>
              <![CDATA[The following asserts failed:
Hording_and_Advertisement_Tab Hit expected [true] but found [false]]]>
            </message>
            <full-stacktrace>
              <![CDATA[java.lang.AssertionError: The following asserts failed:
Hording_and_Advertisement_Tab Hit expected [true] but found [false]
at org.testng.asserts.SoftAssert.assertAll(SoftAssert.java:43)
at com.PageObject.Payment.Application_Status.Hording_and_Advertisement_Tab_Click(Application_Status.java:295)
at com.TestCase.RegistrationandLoginTestCase_Folder.Application_TestCase.Hit_Application(Application_TestCase.java:29)
at sun.reflect.NativeMethodAccessorImpl.invoke0(Native Method)
at sun.reflect.NativeMethodAccessorImpl.invoke(NativeMethodAccessorImpl.java:62)
at sun.reflect.DelegatingMethodAccessorImpl.invoke(DelegatingMethodAccessorImpl.java:43)
at java.lang.reflect.Method.invoke(Method.java:498)
at org.testng.internal.MethodInvocationHelper.invokeMethod(MethodInvocationHelper.java:124)
at org.testng.internal.Invoker.invokeMethod(Invoker.java:583)
at org.testng.internal.Invoker.invokeTestMethod(Invoker.java:719)
at org.testng.internal.Invoker.invokeTestMethods(Invoker.java:989)
at org.testng.internal.TestMethodWorker.invokeTestMethods(TestMethodWorker.java:125)
at org.testng.internal.TestMethodWorker.run(TestMethodWorker.java:109)
at org.testng.TestRunner.privateRun(TestRunner.java:648)
at org.testng.TestRunner.run(TestRunner.java:505)
at org.testng.SuiteRunner.runTest(SuiteRunner.java:455)
at org.testng.SuiteRunner.runSequentially(SuiteRunner.java:450)
at org.testng.SuiteRunner.privateRun(SuiteRunner.java:415)
at org.testng.SuiteRunner.run(SuiteRunner.java:364)
at org.testng.SuiteRunnerWorker.runSuite(SuiteRunnerWorker.java:52)
at org.testng.SuiteRunnerWorker.run(SuiteRunnerWorker.java:84)
at org.testng.TestNG.runSuitesSequentially(TestNG.java:1208)
at org.testng.TestNG.runSuitesLocally(TestNG.java:1137)
at org.testng.TestNG.runSuites(TestNG.java:1049)
at org.testng.TestNG.run(TestNG.java:1017)
at org.testng.IDEARemoteTestNG.run(IDEARemoteTestNG.java:73)
at org.testng.RemoteTestNGStarter.main(RemoteTestNGStarter.java:123)
]]>
            </full-stacktrace>
          </exception> <!-- java.lang.AssertionError -->
          <reporter-output>
          </reporter-output>
        </test-method> <!-- Hit_Application -->
        <test-method status="PASS" signature="Application_Details()[pri:5, instance:com.TestCase.RegistrationandLoginTestCase_Folder.Application_TestCase@6e1567f1]" name="Application_Details" duration-ms="32990" started-at="2019-12-19T08:31:49Z" finished-at="2019-12-19T08:32:22Z">
          <reporter-output>
          </reporter-output>
        </test-method> <!-- Application_Details -->
      </class> <!-- com.TestCase.RegistrationandLoginTestCase_Folder.Application_TestCase -->
    </test> <!-- nEXCITIZEN_TestCase1 -->
  </suite> <!-- nEXCITIZEN -->
</testng-results>
